<mujoco model="sawyer_push">
    <include file="./common/sawyer_noscene.xml" />
    <worldbody>
        <light castshadow="false" ambient="0.05 0.1 0" diffuse="1 1 1" dir="0 -.15 -1" directional="false" pos="1.5 0.7 4.0" specular=".1 .1 .1" />
        <light castshadow="false" ambient="0.05 0.1 0" diffuse="1 1 1" dir="0 -.15 -1" directional="false" pos="-1.5 -0.7 4.0" specular=".1 .1 .1" />

        <geom name="FLOOR" pos="0 0 0" size="5 5 10" material="MatGnd" type="plane" contype="1" conaffinity="1"/>
        <body name="table" pos="0.66 0.0 0.41">
          <geom friction="1 0.005 0.0001" name="table_collision" pos="0 0 0" size="0.4 0.4 0.41" type="box" />
          <geom conaffinity="0" contype="0" group="1" name="table_visual" pos="0 0 0" size="0.4 0.4 0.41" type="box" />
          <site name="table_top" pos="0.0 0.0 0.41" rgba="0.2 0.2 0 0" size="0.001 0.001 0.001" />
        </body>
        <body name="cylinder_body" pos="0.5317717157210129 -0.023869616735809365 0.86" quat="0.8775825618903728 0 0 0.479425538604203">
                <!-- <geom density="400" friction="4.0 0.005 0.0001" group="1" name="cube" pos="0 0 0" rgba="1 0 0 1" size="0.04 0.04 0.04" type="box" /> -->
            <inertial pos="0 0 0" mass="0.01" diaginertia="100000 100000 100000"/>
            <geom contype="1" conaffinity="1" mass="0.03" friction="3 0.005 0.0001" condim="4" group="1" name="cylinder_geom" pos="0 0 0" rgba="1 0 0 1" size="0.04 0.02" type="cylinder" solimp="0.99 0.99 0.01" solref="0.01 1"/>
            <site name="cylinder_site" pos="0 0 0" rgba="1 0 0 1" size="0.002 0.002 0.002" type="sphere" />
            <joint name="cylinder" type="free" />
        </body>
        <body name="target" pos="0.56 0.0 0.82">
            <joint armature="0" axis="1 0 0" damping="0" limited="true" name="target_x" pos="0 0 0" range="-.3 .3" stiffness="0" type="slide"/>
            <joint armature="0" axis="0 1 0" damping="0" limited="true" name="target_y" pos="0 0 0" range="-.3 .3" stiffness="0" type="slide"/>
<!--            <geom conaffinity="0" contype="0" group="0" name="target" pos="0 0 0" rgba="0.5 0.6 0.2 1" size=".030 .001 .001" type="cylinder"/>-->
            <geom conaffinity="0" contype="0" group="0" name="target" pos="0 0 0" rgba="0.15 0.4 0 1" size=".030 .001 .001" type="cylinder"/>
        </body>
    </worldbody>

    <asset>
         <texture builtin="gradient" height="256" rgb1=".9 .9 1." rgb2=".2 .3 .4" type="skybox" width="256" />
         <texture name="plane" type="2d" builtin="flat" rgb1="0.9 0.9 1.0" rgb2="0 0 0" width="512" height="512"/>
         <material name="MatGnd" reflectance="0.5" texture="plane" texrepeat="1 1" texuniform="true"/>
     </asset>
    <visual>
        <headlight diffuse='.8 .6 .4'  ambient='.4 .3 .2' specular='0 0 0'/>
  	</visual>
</mujoco>
